2022-05-11 15:40:25.506 | ERROR    | __main__:<module>:95 - An error has been caught in function '<module>', process 'MainProcess' (23937), thread 'MainThread' (4584781312):
Traceback (most recent call last):

  File "/Library/Frameworks/Python.framework/Versions/3.9/lib/python3.9/site-packages/urllib3/connection.py", line 169, in _new_conn
    conn = connection.create_connection(
           │          └ <function create_connection at 0x7ff46fde1280>
           └ <module 'urllib3.util.connection' from '/Library/Frameworks/Python.framework/Versions/3.9/lib/python3.9/site-packages/urllib3...
  File "/Library/Frameworks/Python.framework/Versions/3.9/lib/python3.9/site-packages/urllib3/util/connection.py", line 96, in create_connection
    raise err
          └ OSError(51, 'Network is unreachable')
  File "/Library/Frameworks/Python.framework/Versions/3.9/lib/python3.9/site-packages/urllib3/util/connection.py", line 86, in create_connection
    sock.connect(sa)
    │            └ ('192.168.1.122', 8500)
    └ None

OSError: [Errno 51] Network is unreachable


During handling of the above exception, another exception occurred:


Traceback (most recent call last):

  File "/Library/Frameworks/Python.framework/Versions/3.9/lib/python3.9/site-packages/urllib3/connectionpool.py", line 699, in urlopen
    httplib_response = self._make_request(
                       │    └ <function HTTPConnectionPool._make_request at 0x7ff46fe33c10>
                       └ <urllib3.connectionpool.HTTPConnectionPool object at 0x7ff46ff6ffa0>
  File "/Library/Frameworks/Python.framework/Versions/3.9/lib/python3.9/site-packages/urllib3/connectionpool.py", line 394, in _make_request
    conn.request(method, url, **httplib_request_kw)
    │    │       │       │      └ {'body': b'{"Name": "user-dao", "ID": "d72d309f-37bc-405f-8e31-254989dd0218", "tags": [], "Port": 4343, "Address": "192.168.1...
    │    │       │       └ '/v1/agent/service/register'
    │    │       └ 'PUT'
    │    └ <function HTTPConnection.request at 0x7ff46fe1ab80>
    └ <urllib3.connection.HTTPConnection object at 0x7ff46ff76ac0>
  File "/Library/Frameworks/Python.framework/Versions/3.9/lib/python3.9/site-packages/urllib3/connection.py", line 234, in request
    super(HTTPConnection, self).request(method, url, body=body, headers=headers)
          │               │             │       │         │             └ {'User-Agent': 'python-requests/2.26.0', 'Accept-Encoding': 'gzip, deflate', 'Accept': '*/*', 'Connection': 'keep-alive', 'Co...
          │               │             │       │         └ b'{"Name": "user-dao", "ID": "d72d309f-37bc-405f-8e31-254989dd0218", "tags": [], "Port": 4343, "Address": "192.168.1.122", "C...
          │               │             │       └ '/v1/agent/service/register'
          │               │             └ 'PUT'
          │               └ <urllib3.connection.HTTPConnection object at 0x7ff46ff76ac0>
          └ <class 'urllib3.connection.HTTPConnection'>
  File "/Library/Frameworks/Python.framework/Versions/3.9/lib/python3.9/http/client.py", line 1279, in request
    self._send_request(method, url, body, headers, encode_chunked)
    │    │             │       │    │     │        └ False
    │    │             │       │    │     └ {'User-Agent': 'python-requests/2.26.0', 'Accept-Encoding': 'gzip, deflate', 'Accept': '*/*', 'Connection': 'keep-alive', 'Co...
    │    │             │       │    └ b'{"Name": "user-dao", "ID": "d72d309f-37bc-405f-8e31-254989dd0218", "tags": [], "Port": 4343, "Address": "192.168.1.122", "C...
    │    │             │       └ '/v1/agent/service/register'
    │    │             └ 'PUT'
    │    └ <function HTTPConnection._send_request at 0x7ff46faf8f70>
    └ <urllib3.connection.HTTPConnection object at 0x7ff46ff76ac0>
  File "/Library/Frameworks/Python.framework/Versions/3.9/lib/python3.9/http/client.py", line 1325, in _send_request
    self.endheaders(body, encode_chunked=encode_chunked)
    │    │          │                    └ False
    │    │          └ b'{"Name": "user-dao", "ID": "d72d309f-37bc-405f-8e31-254989dd0218", "tags": [], "Port": 4343, "Address": "192.168.1.122", "C...
    │    └ <function HTTPConnection.endheaders at 0x7ff46faf8e50>
    └ <urllib3.connection.HTTPConnection object at 0x7ff46ff76ac0>
  File "/Library/Frameworks/Python.framework/Versions/3.9/lib/python3.9/http/client.py", line 1274, in endheaders
    self._send_output(message_body, encode_chunked=encode_chunked)
    │    │            │                            └ False
    │    │            └ b'{"Name": "user-dao", "ID": "d72d309f-37bc-405f-8e31-254989dd0218", "tags": [], "Port": 4343, "Address": "192.168.1.122", "C...
    │    └ <function HTTPConnection._send_output at 0x7ff46faf8a60>
    └ <urllib3.connection.HTTPConnection object at 0x7ff46ff76ac0>
  File "/Library/Frameworks/Python.framework/Versions/3.9/lib/python3.9/http/client.py", line 1034, in _send_output
    self.send(msg)
    │    │    └ b'PUT /v1/agent/service/register HTTP/1.1\r\nHost: 192.168.1.122:8500\r\nUser-Agent: python-requests/2.26.0\r\nAccept-Encodin...
    │    └ <function HTTPConnection.send at 0x7ff46faf88b0>
    └ <urllib3.connection.HTTPConnection object at 0x7ff46ff76ac0>
  File "/Library/Frameworks/Python.framework/Versions/3.9/lib/python3.9/http/client.py", line 974, in send
    self.connect()
    │    └ <function HTTPConnection.connect at 0x7ff46fe1a9d0>
    └ <urllib3.connection.HTTPConnection object at 0x7ff46ff76ac0>
  File "/Library/Frameworks/Python.framework/Versions/3.9/lib/python3.9/site-packages/urllib3/connection.py", line 200, in connect
    conn = self._new_conn()
           │    └ <function HTTPConnection._new_conn at 0x7ff46fe1a820>
           └ <urllib3.connection.HTTPConnection object at 0x7ff46ff76ac0>
  File "/Library/Frameworks/Python.framework/Versions/3.9/lib/python3.9/site-packages/urllib3/connection.py", line 181, in _new_conn
    raise NewConnectionError(
          └ <class 'urllib3.exceptions.NewConnectionError'>

urllib3.exceptions.NewConnectionError: <urllib3.connection.HTTPConnection object at 0x7ff46ff76ac0>: Failed to establish a new connection: [Errno 51] Network is unreachable


During handling of the above exception, another exception occurred:


Traceback (most recent call last):

  File "/Library/Frameworks/Python.framework/Versions/3.9/lib/python3.9/site-packages/requests/adapters.py", line 439, in send
    resp = conn.urlopen(
           │    └ <function HTTPConnectionPool.urlopen at 0x7ff46fe33e50>
           └ <urllib3.connectionpool.HTTPConnectionPool object at 0x7ff46ff6ffa0>
  File "/Library/Frameworks/Python.framework/Versions/3.9/lib/python3.9/site-packages/urllib3/connectionpool.py", line 755, in urlopen
    retries = retries.increment(
              │       └ <function Retry.increment at 0x7ff46fdeba60>
              └ Retry(total=0, connect=None, read=False, redirect=None, status=None)
  File "/Library/Frameworks/Python.framework/Versions/3.9/lib/python3.9/site-packages/urllib3/util/retry.py", line 574, in increment
    raise MaxRetryError(_pool, url, error or ResponseError(cause))
          │             │      │    │        │             └ 'unknown'
          │             │      │    │        └ <class 'urllib3.exceptions.ResponseError'>
          │             │      │    └ NewConnectionError('<urllib3.connection.HTTPConnection object at 0x7ff46ff76ac0>: Failed to establish a new connection: [Errn...
          │             │      └ '/v1/agent/service/register'
          │             └ <urllib3.connectionpool.HTTPConnectionPool object at 0x7ff46ff6ffa0>
          └ <class 'urllib3.exceptions.MaxRetryError'>

urllib3.exceptions.MaxRetryError: HTTPConnectionPool(host='192.168.1.122', port=8500): Max retries exceeded with url: /v1/agent/service/register (Caused by NewConnectionError('<urllib3.connection.HTTPConnection object at 0x7ff46ff76ac0>: Failed to establish a new connection: [Errno 51] Network is unreachable'))


During handling of the above exception, another exception occurred:


Traceback (most recent call last):

> File "/Users/www/learn-note/gpmall/daoServer/user/server.py", line 95, in <module>
    server()
    └ <function server at 0x7ff46ff7adc0>

  File "/Users/www/learn-note/gpmall/daoServer/user/server.py", line 32, in server
    c.register(config.USER_SERVER_HOST, config.USER_SERVER_PORT, config.USER_SERVER_NAME, service_id, )
    │ │        │      │                 │      │                 │      │                 └ 'd72d309f-37bc-405f-8e31-254989dd0218'
    │ │        │      │                 │      │                 │      └ 'user-dao'
    │ │        │      │                 │      │                 └ <module 'config.config' from '/Users/www/learn-note/gpmall/daoServer/user/config/config.py'>
    │ │        │      │                 │      └ 4343
    │ │        │      │                 └ <module 'config.config' from '/Users/www/learn-note/gpmall/daoServer/user/config/config.py'>
    │ │        │      └ '192.168.1.122'
    │ │        └ <module 'config.config' from '/Users/www/learn-note/gpmall/daoServer/user/config/config.py'>
    │ └ <function Consul.register at 0x7ff46ff7ab80>
    └ <common.consul.consul.Consul object at 0x7ff46ff6fdf0>

  File "/Users/www/learn-note/gpmall/daoServer/common/consul/consul.py", line 27, in register
    rsp = requests.put(f"{self.baseUrl}/register", headers=self.headers, json=params)
          │        │                                       │    │             └ {'Name': 'user-dao', 'ID': 'd72d309f-37bc-405f-8e31-254989dd0218', 'tags': [], 'Port': 4343, 'Address': '192.168.1.122', 'Che...
          │        │                                       │    └ {'Content-Type': 'application/json'}
          │        │                                       └ <common.consul.consul.Consul object at 0x7ff46ff6fdf0>
          │        └ <function put at 0x7ff46ff7a820>
          └ <module 'requests' from '/Library/Frameworks/Python.framework/Versions/3.9/lib/python3.9/site-packages/requests/__init__.py'>

  File "/Library/Frameworks/Python.framework/Versions/3.9/lib/python3.9/site-packages/requests/api.py", line 132, in put
    return request('put', url, data=data, **kwargs)
           │              │         │       └ {'headers': {'Content-Type': 'application/json'}, 'json': {'Name': 'user-dao', 'ID': 'd72d309f-37bc-405f-8e31-254989dd0218', ...
           │              │         └ None
           │              └ 'http://192.168.1.122:8500/v1/agent/service/register'
           └ <function request at 0x7ff46ff674c0>
  File "/Library/Frameworks/Python.framework/Versions/3.9/lib/python3.9/site-packages/requests/api.py", line 61, in request
    return session.request(method=method, url=url, **kwargs)
           │       │              │           │      └ {'data': None, 'headers': {'Content-Type': 'application/json'}, 'json': {'Name': 'user-dao', 'ID': 'd72d309f-37bc-405f-8e31-2...
           │       │              │           └ 'http://192.168.1.122:8500/v1/agent/service/register'
           │       │              └ 'put'
           │       └ <function Session.request at 0x7ff46ff75d30>
           └ <requests.sessions.Session object at 0x7ff46ff76370>
  File "/Library/Frameworks/Python.framework/Versions/3.9/lib/python3.9/site-packages/requests/sessions.py", line 542, in request
    resp = self.send(prep, **send_kwargs)
           │    │    │       └ {'timeout': None, 'allow_redirects': True, 'verify': True, 'proxies': OrderedDict(), 'stream': False, 'cert': None}
           │    │    └ <PreparedRequest [PUT]>
           │    └ <function Session.send at 0x7ff46ff7a1f0>
           └ <requests.sessions.Session object at 0x7ff46ff76370>
  File "/Library/Frameworks/Python.framework/Versions/3.9/lib/python3.9/site-packages/requests/sessions.py", line 655, in send
    r = adapter.send(request, **kwargs)
        │       │    │          └ {'timeout': None, 'verify': True, 'proxies': OrderedDict(), 'stream': False, 'cert': None}
        │       │    └ <PreparedRequest [PUT]>
        │       └ <function HTTPAdapter.send at 0x7ff46ff75670>
        └ <requests.adapters.HTTPAdapter object at 0x7ff46ff764f0>
  File "/Library/Frameworks/Python.framework/Versions/3.9/lib/python3.9/site-packages/requests/adapters.py", line 516, in send
    raise ConnectionError(e, request=request)
          │                          └ <PreparedRequest [PUT]>
          └ <class 'requests.exceptions.ConnectionError'>

requests.exceptions.ConnectionError: HTTPConnectionPool(host='192.168.1.122', port=8500): Max retries exceeded with url: /v1/agent/service/register (Caused by NewConnectionError('<urllib3.connection.HTTPConnection object at 0x7ff46ff76ac0>: Failed to establish a new connection: [Errno 51] Network is unreachable'))
2022-05-11 15:40:25.506 | ERROR    | __main__:<module>:95 - An error has been caught in function '<module>', process 'MainProcess' (23937), thread 'MainThread' (4584781312):
Traceback (most recent call last):

  File "/Library/Frameworks/Python.framework/Versions/3.9/lib/python3.9/site-packages/urllib3/connection.py", line 169, in _new_conn
    conn = connection.create_connection(
           │          └ <function create_connection at 0x7ff46fde1280>
           └ <module 'urllib3.util.connection' from '/Library/Frameworks/Python.framework/Versions/3.9/lib/python3.9/site-packages/urllib3...
  File "/Library/Frameworks/Python.framework/Versions/3.9/lib/python3.9/site-packages/urllib3/util/connection.py", line 96, in create_connection
    raise err
          └ OSError(51, 'Network is unreachable')
  File "/Library/Frameworks/Python.framework/Versions/3.9/lib/python3.9/site-packages/urllib3/util/connection.py", line 86, in create_connection
    sock.connect(sa)
    │            └ ('192.168.1.122', 8500)
    └ None

OSError: [Errno 51] Network is unreachable


During handling of the above exception, another exception occurred:


Traceback (most recent call last):

  File "/Library/Frameworks/Python.framework/Versions/3.9/lib/python3.9/site-packages/urllib3/connectionpool.py", line 699, in urlopen
    httplib_response = self._make_request(
                       │    └ <function HTTPConnectionPool._make_request at 0x7ff46fe33c10>
                       └ <urllib3.connectionpool.HTTPConnectionPool object at 0x7ff46ff6ffa0>
  File "/Library/Frameworks/Python.framework/Versions/3.9/lib/python3.9/site-packages/urllib3/connectionpool.py", line 394, in _make_request
    conn.request(method, url, **httplib_request_kw)
    │    │       │       │      └ {'body': b'{"Name": "user-dao", "ID": "d72d309f-37bc-405f-8e31-254989dd0218", "tags": [], "Port": 4343, "Address": "192.168.1...
    │    │       │       └ '/v1/agent/service/register'
    │    │       └ 'PUT'
    │    └ <function HTTPConnection.request at 0x7ff46fe1ab80>
    └ <urllib3.connection.HTTPConnection object at 0x7ff46ff76ac0>
  File "/Library/Frameworks/Python.framework/Versions/3.9/lib/python3.9/site-packages/urllib3/connection.py", line 234, in request
    super(HTTPConnection, self).request(method, url, body=body, headers=headers)
          │               │             │       │         │             └ {'User-Agent': 'python-requests/2.26.0', 'Accept-Encoding': 'gzip, deflate', 'Accept': '*/*', 'Connection': 'keep-alive', 'Co...
          │               │             │       │         └ b'{"Name": "user-dao", "ID": "d72d309f-37bc-405f-8e31-254989dd0218", "tags": [], "Port": 4343, "Address": "192.168.1.122", "C...
          │               │             │       └ '/v1/agent/service/register'
          │               │             └ 'PUT'
          │               └ <urllib3.connection.HTTPConnection object at 0x7ff46ff76ac0>
          └ <class 'urllib3.connection.HTTPConnection'>
  File "/Library/Frameworks/Python.framework/Versions/3.9/lib/python3.9/http/client.py", line 1279, in request
    self._send_request(method, url, body, headers, encode_chunked)
    │    │             │       │    │     │        └ False
    │    │             │       │    │     └ {'User-Agent': 'python-requests/2.26.0', 'Accept-Encoding': 'gzip, deflate', 'Accept': '*/*', 'Connection': 'keep-alive', 'Co...
    │    │             │       │    └ b'{"Name": "user-dao", "ID": "d72d309f-37bc-405f-8e31-254989dd0218", "tags": [], "Port": 4343, "Address": "192.168.1.122", "C...
    │    │             │       └ '/v1/agent/service/register'
    │    │             └ 'PUT'
    │    └ <function HTTPConnection._send_request at 0x7ff46faf8f70>
    └ <urllib3.connection.HTTPConnection object at 0x7ff46ff76ac0>
  File "/Library/Frameworks/Python.framework/Versions/3.9/lib/python3.9/http/client.py", line 1325, in _send_request
    self.endheaders(body, encode_chunked=encode_chunked)
    │    │          │                    └ False
    │    │          └ b'{"Name": "user-dao", "ID": "d72d309f-37bc-405f-8e31-254989dd0218", "tags": [], "Port": 4343, "Address": "192.168.1.122", "C...
    │    └ <function HTTPConnection.endheaders at 0x7ff46faf8e50>
    └ <urllib3.connection.HTTPConnection object at 0x7ff46ff76ac0>
  File "/Library/Frameworks/Python.framework/Versions/3.9/lib/python3.9/http/client.py", line 1274, in endheaders
    self._send_output(message_body, encode_chunked=encode_chunked)
    │    │            │                            └ False
    │    │            └ b'{"Name": "user-dao", "ID": "d72d309f-37bc-405f-8e31-254989dd0218", "tags": [], "Port": 4343, "Address": "192.168.1.122", "C...
    │    └ <function HTTPConnection._send_output at 0x7ff46faf8a60>
    └ <urllib3.connection.HTTPConnection object at 0x7ff46ff76ac0>
  File "/Library/Frameworks/Python.framework/Versions/3.9/lib/python3.9/http/client.py", line 1034, in _send_output
    self.send(msg)
    │    │    └ b'PUT /v1/agent/service/register HTTP/1.1\r\nHost: 192.168.1.122:8500\r\nUser-Agent: python-requests/2.26.0\r\nAccept-Encodin...
    │    └ <function HTTPConnection.send at 0x7ff46faf88b0>
    └ <urllib3.connection.HTTPConnection object at 0x7ff46ff76ac0>
  File "/Library/Frameworks/Python.framework/Versions/3.9/lib/python3.9/http/client.py", line 974, in send
    self.connect()
    │    └ <function HTTPConnection.connect at 0x7ff46fe1a9d0>
    └ <urllib3.connection.HTTPConnection object at 0x7ff46ff76ac0>
  File "/Library/Frameworks/Python.framework/Versions/3.9/lib/python3.9/site-packages/urllib3/connection.py", line 200, in connect
    conn = self._new_conn()
           │    └ <function HTTPConnection._new_conn at 0x7ff46fe1a820>
           └ <urllib3.connection.HTTPConnection object at 0x7ff46ff76ac0>
  File "/Library/Frameworks/Python.framework/Versions/3.9/lib/python3.9/site-packages/urllib3/connection.py", line 181, in _new_conn
    raise NewConnectionError(
          └ <class 'urllib3.exceptions.NewConnectionError'>

urllib3.exceptions.NewConnectionError: <urllib3.connection.HTTPConnection object at 0x7ff46ff76ac0>: Failed to establish a new connection: [Errno 51] Network is unreachable


During handling of the above exception, another exception occurred:


Traceback (most recent call last):

  File "/Library/Frameworks/Python.framework/Versions/3.9/lib/python3.9/site-packages/requests/adapters.py", line 439, in send
    resp = conn.urlopen(
           │    └ <function HTTPConnectionPool.urlopen at 0x7ff46fe33e50>
           └ <urllib3.connectionpool.HTTPConnectionPool object at 0x7ff46ff6ffa0>
  File "/Library/Frameworks/Python.framework/Versions/3.9/lib/python3.9/site-packages/urllib3/connectionpool.py", line 755, in urlopen
    retries = retries.increment(
              │       └ <function Retry.increment at 0x7ff46fdeba60>
              └ Retry(total=0, connect=None, read=False, redirect=None, status=None)
  File "/Library/Frameworks/Python.framework/Versions/3.9/lib/python3.9/site-packages/urllib3/util/retry.py", line 574, in increment
    raise MaxRetryError(_pool, url, error or ResponseError(cause))
          │             │      │    │        │             └ 'unknown'
          │             │      │    │        └ <class 'urllib3.exceptions.ResponseError'>
          │             │      │    └ NewConnectionError('<urllib3.connection.HTTPConnection object at 0x7ff46ff76ac0>: Failed to establish a new connection: [Errn...
          │             │      └ '/v1/agent/service/register'
          │             └ <urllib3.connectionpool.HTTPConnectionPool object at 0x7ff46ff6ffa0>
          └ <class 'urllib3.exceptions.MaxRetryError'>

urllib3.exceptions.MaxRetryError: HTTPConnectionPool(host='192.168.1.122', port=8500): Max retries exceeded with url: /v1/agent/service/register (Caused by NewConnectionError('<urllib3.connection.HTTPConnection object at 0x7ff46ff76ac0>: Failed to establish a new connection: [Errno 51] Network is unreachable'))


During handling of the above exception, another exception occurred:


Traceback (most recent call last):

> File "/Users/www/learn-note/gpmall/daoServer/user/server.py", line 95, in <module>
    server()
    └ <function server at 0x7ff46ff7adc0>

  File "/Users/www/learn-note/gpmall/daoServer/user/server.py", line 32, in server
    c.register(config.USER_SERVER_HOST, config.USER_SERVER_PORT, config.USER_SERVER_NAME, service_id, )
    │ │        │      │                 │      │                 │      │                 └ 'd72d309f-37bc-405f-8e31-254989dd0218'
    │ │        │      │                 │      │                 │      └ 'user-dao'
    │ │        │      │                 │      │                 └ <module 'config.config' from '/Users/www/learn-note/gpmall/daoServer/user/config/config.py'>
    │ │        │      │                 │      └ 4343
    │ │        │      │                 └ <module 'config.config' from '/Users/www/learn-note/gpmall/daoServer/user/config/config.py'>
    │ │        │      └ '192.168.1.122'
    │ │        └ <module 'config.config' from '/Users/www/learn-note/gpmall/daoServer/user/config/config.py'>
    │ └ <function Consul.register at 0x7ff46ff7ab80>
    └ <common.consul.consul.Consul object at 0x7ff46ff6fdf0>

  File "/Users/www/learn-note/gpmall/daoServer/common/consul/consul.py", line 27, in register
    rsp = requests.put(f"{self.baseUrl}/register", headers=self.headers, json=params)
          │        │                                       │    │             └ {'Name': 'user-dao', 'ID': 'd72d309f-37bc-405f-8e31-254989dd0218', 'tags': [], 'Port': 4343, 'Address': '192.168.1.122', 'Che...
          │        │                                       │    └ {'Content-Type': 'application/json'}
          │        │                                       └ <common.consul.consul.Consul object at 0x7ff46ff6fdf0>
          │        └ <function put at 0x7ff46ff7a820>
          └ <module 'requests' from '/Library/Frameworks/Python.framework/Versions/3.9/lib/python3.9/site-packages/requests/__init__.py'>

  File "/Library/Frameworks/Python.framework/Versions/3.9/lib/python3.9/site-packages/requests/api.py", line 132, in put
    return request('put', url, data=data, **kwargs)
           │              │         │       └ {'headers': {'Content-Type': 'application/json'}, 'json': {'Name': 'user-dao', 'ID': 'd72d309f-37bc-405f-8e31-254989dd0218', ...
           │              │         └ None
           │              └ 'http://192.168.1.122:8500/v1/agent/service/register'
           └ <function request at 0x7ff46ff674c0>
  File "/Library/Frameworks/Python.framework/Versions/3.9/lib/python3.9/site-packages/requests/api.py", line 61, in request
    return session.request(method=method, url=url, **kwargs)
           │       │              │           │      └ {'data': None, 'headers': {'Content-Type': 'application/json'}, 'json': {'Name': 'user-dao', 'ID': 'd72d309f-37bc-405f-8e31-2...
           │       │              │           └ 'http://192.168.1.122:8500/v1/agent/service/register'
           │       │              └ 'put'
           │       └ <function Session.request at 0x7ff46ff75d30>
           └ <requests.sessions.Session object at 0x7ff46ff76370>
  File "/Library/Frameworks/Python.framework/Versions/3.9/lib/python3.9/site-packages/requests/sessions.py", line 542, in request
    resp = self.send(prep, **send_kwargs)
           │    │    │       └ {'timeout': None, 'allow_redirects': True, 'verify': True, 'proxies': OrderedDict(), 'stream': False, 'cert': None}
           │    │    └ <PreparedRequest [PUT]>
           │    └ <function Session.send at 0x7ff46ff7a1f0>
           └ <requests.sessions.Session object at 0x7ff46ff76370>
  File "/Library/Frameworks/Python.framework/Versions/3.9/lib/python3.9/site-packages/requests/sessions.py", line 655, in send
    r = adapter.send(request, **kwargs)
        │       │    │          └ {'timeout': None, 'verify': True, 'proxies': OrderedDict(), 'stream': False, 'cert': None}
        │       │    └ <PreparedRequest [PUT]>
        │       └ <function HTTPAdapter.send at 0x7ff46ff75670>
        └ <requests.adapters.HTTPAdapter object at 0x7ff46ff764f0>
  File "/Library/Frameworks/Python.framework/Versions/3.9/lib/python3.9/site-packages/requests/adapters.py", line 516, in send
    raise ConnectionError(e, request=request)
          │                          └ <PreparedRequest [PUT]>
          └ <class 'requests.exceptions.ConnectionError'>

requests.exceptions.ConnectionError: HTTPConnectionPool(host='192.168.1.122', port=8500): Max retries exceeded with url: /v1/agent/service/register (Caused by NewConnectionError('<urllib3.connection.HTTPConnection object at 0x7ff46ff76ac0>: Failed to establish a new connection: [Errno 51] Network is unreachable'))
2022-05-11 15:41:09.291 | INFO     | __main__:server:39 - user-dao 服务启动：192.168.8.222:4343 ...
2022-05-11 15:41:09.291 | INFO     | __main__:server:39 - user-dao 服务启动：192.168.8.222:4343 ...
2022-05-11 16:09:04.592 | INFO     | __main__:server:39 - user-dao 服务启动：192.168.8.222:4343 ...
2022-05-11 16:09:04.592 | INFO     | __main__:server:39 - user-dao 服务启动：192.168.8.222:4343 ...
